Workbook
Name Blank_01: Rename_Multiple_Files!$G$17
Name Blank_02: Rename_Multiple_Files!$H$17
Name Blank1: Rename_Multiple_Files!#REF!
Name Blank2: Rename_Multiple_Files!#REF!
Name DateLastModified: Rename_Multiple_Files!$F$17
Name Dummy: Rename_Multiple_Files!#REF!
Name Extension: Rename_Multiple_Files!$E$17
Name FileName: Rename_Multiple_Files!$D$17
Name FileNumber: Rename_Multiple_Files!$B$17
Name FilePath: Rename_Multiple_Files!$I$8
Name FinalName: Rename_Multiple_Files!$K$17
Name FullPath: Rename_Multiple_Files!$C$17
Name NewName: Rename_Multiple_Files!$I$17
Name Override: Rename_Multiple_Files!$J$17
Name Prefix: Rename_Multiple_Files!$I$11
Name ReplaceWhat: Rename_Multiple_Files!$I$9
Name ReplaceWith: Rename_Multiple_Files!$I$10
Name Suffix: Rename_Multiple_Files!$I$12

Sheet Rename_Multiple_Files
F8: File Path | H8: FilePath
D9: You know what | F9: Replace What | H9: ReplaceWhat
F10: Replace With | H10: ReplaceWith
F11: Prefix | H11: Prefix
F12: Suffix | H12: Suffix
B14: No. | C14: Full Path | D14: File Name | E14: Extension | F14: Date Last Modified | G14: Blank 01 | H14: Blank 02 | I14: New Name | J14: Override | K14: Final Name
B16: FileNumber | C16: FullPath | D16: FileName | E16: Extension | F16: DateLastModified | G16: Blank_01 | H16: Blank_02 | I16: NewName | J16: Override | K16: FinalName

Sheet List of Files
A1: File Name | B1: Folder/ Path

Sheet Cover (2)
B2: This Excel macro will help you get an inventory of all the file you have in a certain folder.
B4: Instructions
B5: Go to List of Files tab
B6: Make sure that running macros is enabled in your security settings:
C7: >>> | D7: https://bit.ly/3AdZyFo
B8: Open Run Macro Window (Alt+F8)
B9: Select the command MainList and press Run.
B10: In the pop-up window, navigate to the directory for which you want to generate the list, and click Ok.
B11: Done! ☺
B15: About me
B16: For any updates, changes or inconsistencies, you can contact me at:
B17: Etsy: | C17: https://thinkingintables.etsy.com/
B18: LinkedIn: | C18: https://www.linkedin.com/in/pangheadrian/
B19: Email: | C19: pangheadrian@gmail.com
C20: pangheadrian@yahoo.com
B22: Document details
B23: Document: | C23: Automatic List of Files in Directory
B24: Date: | C24: 44798
B25: Version: | C25: 1.2

Sheet Data
B1: File Name | C1: Target Folder Name (or Subfolder path) | E1: Check >>> | F1: =IF(AND(RIGHT($F$2,1)="\", RIGHT($F$3,1)="\"), "Paths seem ok.", "Attention! Both paths should end with a backslash --> \") -> Attention! Both paths should end with a backslash --> \
B2: Holiday_Picture_001.jpg | C2: France | E2: Source Path: | F2: >> enter source folder path here <<<
B3: Holiday_Picture_002.jpg | C3: France\Paris | E3: Target Path: | F3: >> enter target folder path here <<<
B4: Holiday_Picture_003.jpg | C4: France\Paris
B5: Holiday_Picture_004.jpg | C5: England
B6: Holiday_Picture_005.jpg | C6: England
B7: Holiday_Picture_006.jpg | C7: England\London

Sheet Cover
B2: This Excel macro will help you move multiple files in various folders and subfolders, all at once.
B4: Instructions
B5: Make sure that running macros is enabled in your security settings:
C6: >>> | D6: https://bit.ly/3AdZyFo
B7: Go to Data tab
B8: Enter Source path and Target path in column F.
B9: Enter the name of all the files to be move in column B.
C10: If you need to generate a list of all the files in a folder, us the following:
C11: >>> | D11: https://www.etsy.com/uk/listing/1201821787/productivity-hack-automatic-list-of?click_key=1bc3b481990db969127c1150d34812d44118de20%3A1201821787&click_sum=cc70c1f8&ref=shop_home_feat_1
B12: Enter the target folder or subfolder for each file in column C.
B13: Open Run Macro Window (Alt+F8)
B14: Select the command MoveFiles and press Run.
B15: Done! ☺
B17: Thanks to Stackoverflow for this thread:
B18: https://stackoverflow.com/questions/46508937/excel-vba-code-moving-multiple-files-to-specific-folders
B20: About me
B21: For any updates, changes or inconsistencies, you can contact me at:
B22: Etsy: | C22: https://thinkingintables.etsy.com/
B23: LinkedIn: | C23: https://www.linkedin.com/in/pangheadrian/
B24: Email: | C24: pangheadrian@gmail.com
C25: pangheadrian@yahoo.com
B27: Document details
B28: Document: | C28: Move Files to Folders
B29: Date: | C29: 44815
B30: Version: | C30: 1,0

Sheet Dashboard
A1: FIS Rule + Automation Grammar
A2: Master workbook for the File Intelligence System: selection grammar, action grammar, guardrails, views, symptoms, simulations, and Python-readable specs.
A4: Metric | B4: Value | C4: Meaning | E4: Stage | F4: What it means | G4: Primary sheets
A5: Fields | B5: =COUNTA(Fields!A5:A67) -> 63 | C5: Selectable file properties | E5: 1. Selection | F5: Find the files/folders. Field → operator → value. | G5: Rule_Builder, Fields, Operators
A6: Operators | B6: =COUNTA(Operators!A5:A39) -> 35 | C6: Filter operations | E6: 2. Diagnosis | F6: Detect symptoms and risk before any action. | G6: Symptoms, Guardrails
A7: Actions | B7: =COUNTA(Actions_Master!A5:A36) -> 32 | C7: Action registry | E7: 3. Plan | F7: Choose the sequence and compatible actions. | G7: Action_Map, Action_Sequence_Matrix
A8: Guardrails | B8: =COUNTA(Guardrails!A5:A16) -> 12 | C8: Non-negotiable safety rules | E8: 4. Preview | F8: Show exact before/after, required guardrails, and review queue. | G8: Simulation_Lab, Compatibility_Matrix
A9: Symptoms | B9: =COUNTA(Symptoms!A5:A44) -> 40 | C9: Detected file/folder pathologies | E9: 5. Approve | F9: Human confirms/edit/rejects; this trains the preference engine later. | G9: Automation_Rules, Ledger_Schema
A10: Workflows | B10: =COUNTA(Workflow_Templates!A5:A12) -> 8 | C10: Reusable consulting playbooks | E10: 6. Record | F10: Every action writes to ledger and report. | G10: Report_Sections, Ledger_Schema
A11: Compatibility Rules | B11: =COUNTA(Compatibility_Matrix!A5:A28) -> 24 | C11: Known action pair rules
E13: Action Family | F13: Count
A14: Core Rules | E14: Action | F14: =COUNTIF(Actions_Master!C5:C36,"Action") -> 5
A15: A filter finds files. An automation rule decides what to do. A guardrail decides what must never happen. | E15: Analyze | F15: =COUNTIF(Actions_Master!C5:C36,"Analyze") -> 6
E16: Automation | F16: =COUNTIF(Actions_Master!C5:C36,"Automation") -> 3
E17: Govern | F17: =COUNTIF(Actions_Master!C5:C36,"Govern") -> 1
E18: Inspect | F18: =COUNTIF(Actions_Master!C5:C36,"Inspect") -> 4
E19: Integration | F19: =COUNTIF(Actions_Master!C5:C36,"Integration") -> 3
E20: Metadata | F20: =COUNTIF(Actions_Master!C5:C36,"Metadata") -> 3
E21: Risk | F21: =COUNTIF(Actions_Master!C5:C36,"Risk") -> 2
E22: Safety | F22: =COUNTIF(Actions_Master!C5:C36,"Safety") -> 2
E23: Scaffold | F23: =COUNTIF(Actions_Master!C5:C36,"Scaffold") -> 3

Sheet Rule_Builder
A1: Let me just let you look at it real fast
A2: Field → operator → value. This finds a file set. Actions and automation are separate.
A4: rule_id | B4: enabled | C4: AND_OR | D4: field | E4: field_type | F4: operator | G4: operator_type | H4: operator_valid | I4: value | J4: action | K4: target/parameter | L4: guardrail | M4: view_mode | N4: approval_mode | O4: notes
A5: RULE-001 | B5: TRUE | C5: AND | D5: path | E5: =IFERROR(INDEX(Fields!$C$5:$C$67,MATCH(D5,Fields!$A$5:$A$67,0)),"") -> text | F5: contains | G5: =IFERROR(INDEX(Operators!$C$5:$C$39,MATCH(F5,Operators!$B$5:$B$39,0)),"") -> text | H5: =IF(D5="","",IF(F5="","",IF(ISNUMBER(SEARCH(INDEX(Operators!$A$5:$A$39,MATCH(F5,Operators!$B$5:$B$39,0)),INDEX(Fields!$G$5:$G$67,MATCH(D5,Fields!$A$5:$A$67,0)))),"OK","CHECK"))) -> OK | I5: Downloads | J5: classify | L5: GR-006 | M5: details | N5: preview_only | O5: Start by classifying downloads
A6: RULE-002 | B6: TRUE | C6: AND | D6: type | E6: =IFERROR(INDEX(Fields!$C$5:$C$67,MATCH(D6,Fields!$A$5:$A$67,0)),"") -> category | F6: is | G6: =IFERROR(INDEX(Operators!$C$5:$C$39,MATCH(F6,Operators!$B$5:$B$39,0)),"") -> category | H6: =IF(D6="","",IF(F6="","",IF(ISNUMBER(SEARCH(INDEX(Operators!$A$5:$A$39,MATCH(F6,Operators!$B$5:$B$39,0)),INDEX(Fields!$G$5:$G$67,MATCH(D6,Fields!$A$5:$A$67,0)))),"OK","CHECK"))) -> OK | I6: image | J6: move | K6: Pictures\Screenshots\Review | L6: GR-006 | M6: thumbnail | N6: approval_required | O6: Image route candidate
A7: RULE-003 | B7: TRUE | C7: AND | D7: date_modified | E7: =IFERROR(INDEX(Fields!$C$5:$C$67,MATCH(D7,Fields!$A$5:$A$67,0)),"") -> date | F7: older_than_days | G7: =IFERROR(INDEX(Operators!$C$5:$C$39,MATCH(F7,Operators!$B$5:$B$39,0)),"") -> date | H7: =IF(D7="","",IF(F7="","",IF(ISNUMBER(SEARCH(INDEX(Operators!$A$5:$A$39,MATCH(F7,Operators!$B$5:$B$39,0)),INDEX(Fields!$G$5:$G$67,MATCH(D7,Fields!$A$5:$A$67,0)))),"OK","CHECK"))) -> OK | I7: 90 | J7: archive | K7: Archive\Old_Downloads | L7: GR-006 | M7: details | N7: approval_required | O7: Old loose files
A8: RULE-004 | B8: TRUE | C8: AND | D8: name | E8: =IFERROR(INDEX(Fields!$C$5:$C$67,MATCH(D8,Fields!$A$5:$A$67,0)),"") -> text | F8: regex | G8: =IFERROR(INDEX(Operators!$C$5:$C$39,MATCH(F8,Operators!$B$5:$B$39,0)),"") -> text | H8: =IF(D8="","",IF(F8="","",IF(ISNUMBER(SEARCH(INDEX(Operators!$A$5:$A$39,MATCH(F8,Operators!$B$5:$B$39,0)),INDEX(Fields!$G$5:$G$67,MATCH(D8,Fields!$A$5:$A$67,0)))),"OK","CHECK"))) -> OK | I8: (?i)final|draft|v\d+ | J8: detect_symptoms | K8: version_sprawl | L8: GR-005 | M8: grouped | N8: preview_only | O8: Find version sprawl
A9: RULE-005 | B9: TRUE | C9: AND | D9: extension | E9: =IFERROR(INDEX(Fields!$C$5:$C$67,MATCH(D9,Fields!$A$5:$A$67,0)),"") -> category | F9: is | G9: =IFERROR(INDEX(Operators!$C$5:$C$39,MATCH(F9,Operators!$B$5:$B$39,0)),"") -> category | H9: =IF(D9="","",IF(F9="","",IF(ISNUMBER(SEARCH(INDEX(Operators!$A$5:$A$39,MATCH(F9,Operators!$B$5:$B$39,0)),INDEX(Fields!$G$5:$G$67,MATCH(D9,Fields!$A$5:$A$67,0)))),"OK","CHECK"))) -> OK | I9: .env | J9: protect | K9: Do_Not_Touch | L9: GR-004 | M9: details | N9: blocked | O9: Secrets/config protection
A10: RULE-006 | B10: FALSE | C10: AND | E10: =IFERROR(INDEX(Fields!$C$5:$C$67,MATCH(D10,Fields!$A$5:$A$67,0)),"") | G10: =IFERROR(INDEX(Operators!$C$5:$C$39,MATCH(F10,Operators!$B$5:$B$39,0)),"") | H10: =IF(D10="","",IF(F10="","",IF(ISNUMBER(SEARCH(INDEX(Operators!$A$5:$A$39,MATCH(F10,Operators!$B$5:$B$39,0)),INDEX(Fields!$G$5:$G$67,MATCH(D10,Fields!$A$5:$A$67,0)))),"OK","CHECK")))
A11: RULE-007 | B11: FALSE | C11: AND | E11: =IFERROR(INDEX(Fields!$C$5:$C$67,MATCH(D11,Fields!$A$5:$A$67,0)),"") | G11: =IFERROR(INDEX(Operators!$C$5:$C$39,MATCH(F11,Operators!$B$5:$B$39,0)),"") | H11: =IF(D11="","",IF(F11="","",IF(ISNUMBER(SEARCH(INDEX(Operators!$A$5:$A$39,MATCH(F11,Operators!$B$5:$B$39,0)),INDEX(Fields!$G$5:$G$67,MATCH(D11,Fields!$A$5:$A$67,0)))),"OK","CHECK")))
A12: RULE-008 | B12: FALSE | C12: AND | E12: =IFERROR(INDEX(Fields!$C$5:$C$67,MATCH(D12,Fields!$A$5:$A$67,0)),"") | G12: =IFERROR(INDEX(Operators!$C$5:$C$39,MATCH(F12,Operators!$B$5:$B$39,0)),"") | H12: =IF(D12="","",IF(F12="","",IF(ISNUMBER(SEARCH(INDEX(Operators!$A$5:$A$39,MATCH(F12,Operators!$B$5:$B$39,0)),INDEX(Fields!$G$5:$G$67,MATCH(D12,Fields!$A$5:$A$67,0)))),"OK","CHECK")))
A13: RULE-009 | B13: FALSE | C13: AND | E13: =IFERROR(INDEX(Fields!$C$5:$C$67,MATCH(D13,Fields!$A$5:$A$67,0)),"") | G13: =IFERROR(INDEX(Operators!$C$5:$C$39,MATCH(F13,Operators!$B$5:$B$39,0)),"") | H13: =IF(D13="","",IF(F13="","",IF(ISNUMBER(SEARCH(INDEX(Operators!$A$5:$A$39,MATCH(F13,Operators!$B$5:$B$39,0)),INDEX(Fields!$G$5:$G$67,MATCH(D13,Fields!$A$5:$A$67,0)))),"OK","CHECK")))
A14: RULE-010 | B14: FALSE | C14: AND | E14: =IFERROR(INDEX(Fields!$C$5:$C$67,MATCH(D14,Fields!$A$5:$A$67,0)),"") | G14: =IFERROR(INDEX(Operators!$C$5:$C$39,MATCH(F14,Operators!$B$5:$B$39,0)),"") | H14: =IF(D14="","",IF(F14="","",IF(ISNUMBER(SEARCH(INDEX(Operators!$A$5:$A$39,MATCH(F14,Operators!$B$5:$B$39,0)),INDEX(Fields!$G$5:$G$67,MATCH(D14,Fields!$A$5:$A$67,0)))),"OK","CHECK")))
A15: RULE-011 | B15: FALSE | C15: AND | E15: =IFERROR(INDEX(Fields!$C$5:$C$67,MATCH(D15,Fields!$A$5:$A$67,0)),"") | G15: =IFERROR(INDEX(Operators!$C$5:$C$39,MATCH(F15,Operators!$B$5:$B$39,0)),"") | H15: =IF(D15="","",IF(F15="","",IF(ISNUMBER(SEARCH(INDEX(Operators!$A$5:$A$39,MATCH(F15,Operators!$B$5:$B$39,0)),INDEX(Fields!$G$5:$G$67,MATCH(D15,Fields!$A$5:$A$67,0)))),"OK","CHECK")))
A16: RULE-012 | B16: FALSE | C16: AND | E16: =IFERROR(INDEX(Fields!$C$5:$C$67,MATCH(D16,Fields!$A$5:$A$67,0)),"") | G16: =IFERROR(INDEX(Operators!$C$5:$C$39,MATCH(F16,Operators!$B$5:$B$39,0)),"") | H16: =IF(D16="","",IF(F16="","",IF(ISNUMBER(SEARCH(INDEX(Operators!$A$5:$A$39,MATCH(F16,Operators!$B$5:$B$39,0)),INDEX(Fields!$G$5:$G$67,MATCH(D16,Fields!$A$5:$A$67,0)))),"OK","CHECK")))
A17: RULE-013 | B17: FALSE | C17: AND | E17: =IFERROR(INDEX(Fields!$C$5:$C$67,MATCH(D17,Fields!$A$5:$A$67,0)),"") | G17: =IFERROR(INDEX(Operators!$C$5:$C$39,MATCH(F17,Operators!$B$5:$B$39,0)),"") | H17: =IF(D17="","",IF(F17="","",IF(ISNUMBER(SEARCH(INDEX(Operators!$A$5:$A$39,MATCH(F17,Operators!$B$5:$B$39,0)),INDEX(Fields!$G$5:$G$67,MATCH(D17,Fields!$A$5:$A$67,0)))),"OK","CHECK")))
A18: RULE-014 | B18: FALSE | C18: AND | E18: =IFERROR(INDEX(Fields!$C$5:$C$67,MATCH(D18,Fields!$A$5:$A$67,0)),"") | G18: =IFERROR(INDEX(Operators!$C$5:$C$39,MATCH(F18,Operators!$B$5:$B$39,0)),"") | H18: =IF(D18="","",IF(F18="","",IF(ISNUMBER(SEARCH(INDEX(Operators!$A$5:$A$39,MATCH(F18,Operators!$B$5:$B$39,0)),INDEX(Fields!$G$5:$G$67,MATCH(D18,Fields!$A$5:$A$67,0)))),"OK","CHECK")))
A19: RULE-015 | B19: FALSE | C19: AND | E19: =IFERROR(INDEX(Fields!$C$5:$C$67,MATCH(D19,Fields!$A$5:$A$67,0)),"") | G19: =IFERROR(INDEX(Operators!$C$5:$C$39,MATCH(F19,Operators!$B$5:$B$39,0)),"") | H19: =IF(D19="","",IF(F19="","",IF(ISNUMBER(SEARCH(INDEX(Operators!$A$5:$A$39,MATCH(F19,Operators!$B$5:$B$39,0)),INDEX(Fields!$G$5:$G$67,MATCH(D19,Fields!$A$5:$A$67,0)))),"OK","CHECK")))
A20: RULE-016 | B20: FALSE | C20: AND | E20: =IFERROR(INDEX(Fields!$C$5:$C$67,MATCH(D20,Fields!$A$5:$A$67,0)),"") | G20: =IFERROR(INDEX(Operators!$C$5:$C$39,MATCH(F20,Operators!$B$5:$B$39,0)),"") | H20: =IF(D20="","",IF(F20="","",IF(ISNUMBER(SEARCH(INDEX(Operators!$A$5:$A$39,MATCH(F20,Operators!$B$5:$B$39,0)),INDEX(Fields!$G$5:$G$67,MATCH(D20,Fields!$A$5:$A$67,0)))),"OK","CHECK")))
A21: RULE-017 | B21: FALSE | C21: AND | E21: =IFERROR(INDEX(Fields!$C$5:$C$67,MATCH(D21,Fields!$A$5:$A$67,0)),"") | G21: =IFERROR(INDEX(Operators!$C$5:$C$39,MATCH(F21,Operators!$B$5:$B$39,0)),"") | H21: =IF(D21="","",IF(F21="","",IF(ISNUMBER(SEARCH(INDEX(Operators!$A$5:$A$39,MATCH(F21,Operators!$B$5:$B$39,0)),INDEX(Fields!$G$5:$G$67,MATCH(D21,Fields!$A$5:$A$67,0)))),"OK","CHECK")))
... A44: RULE-040 | B44: FALSE | C44: AND | E44: =IFERROR(INDEX(Fields!$C$5:$C$67,MATCH(D44,Fields!$A$5:$A$67,0)),"") | G44: =IFERROR(INDEX(Operators!$C$5:$C$39,MATCH(F44,Operators!$B$5:$B$39,0)),"") | H44: =IF(D44="","",IF(F44="","",IF(ISNUMBER(SEARCH(INDEX(Operators!$A$5:$A$39,MATCH(F44,Operators!$B$5:$B$39,0)),INDEX(Fields!$G$5:$G$67,MATCH(D44,Fields!$A$5:$A$67,0)))),"OK","CHECK")))

Sheet Fields
A1: Fields Registry
A2: All selectable fields/properties for the FIS rule builder. The operator IDs column controls what should be valid.
A4: field_id | B4: display_name | C4: data_type | D4: applies_to | E4: description | F4: example | G4: allowed_operator_ids
A5: name | B5: Name | C5: text | D5: all files/folders | E5: Filename including extension | F5: invoice_2024.xlsx | G5: text.contains,text.starts_with,text.ends_with,text.equals,text.not_contains,text.regex
A6: stem | B6: Stem | C6: text | D6: all files | E6: Filename without extension | F6: invoice_2024 | G6: text.contains,text.starts_with,text.ends_with,text.equals,text.not_contains,text.regex
A7: extension | B7: Extension | C7: category | D7: all files | E7: File extension or [none] | F7: .xlsx | G7: cat.is,cat.is_not,cat.in,cat.not_in,text.equals,text.regex
A8: path | B8: Path | C8: text | D8: all objects | E8: Full path | F8: D:\\Docs\\invoice.xlsx | G8: text.contains,text.starts_with,text.ends_with,text.equals,text.not_contains,text.regex
A9: folder | B9: Folder | C9: text | D9: all objects | E9: Parent folder path/name | F9: Downloads | G9: text.contains,text.starts_with,text.ends_with,text.equals,text.not_contains,text.regex
A10: type | B10: Type | C10: category | D10: all files | E10: File type family | F10: document/image/code/config | G10: cat.is,cat.is_not,cat.in,cat.not_in
A11: detected_type | B11: Detected Type | C11: category | D11: all files | E11: MIME/Magika/Tika detected type | F11: application/pdf | G11: cat.is,cat.is_not,cat.in,cat.not_in,text.contains
A12: mime_type | B12: MIME Type | C12: category | D12: all files | E12: MIME type from detector | F12: image/png | G12: cat.is,cat.is_not,cat.in,cat.not_in,text.contains
A13: size_bytes | B13: Size Bytes | C13: number | D13: all files | E13: File size in bytes | F13: 1048576 | G13: num.gt,num.gte,num.lt,num.lte,num.eq,num.neq,num.between
A14: size_mb | B14: Size MB | C14: number | D14: all files | E14: File size in MB | F14: 12.4 | G14: num.gt,num.gte,num.lt,num.lte,num.eq,num.neq,num.between
A15: tag | B15: Tag | C15: text | D15: sidecar/tagged objects | E15: User/system tag | F15: canonical | G15: text.contains,text.starts_with,text.ends_with,text.equals,text.not_contains,text.regex,text.empty,text.not_empty
A16: content | B16: Content | C16: text | D16: text/doc/pdf/html | E16: Extracted text sample | F16: claim/evidence/source | G16: text.contains,text.not_contains,text.regex,text.empty,text.not_empty
A17: hash_sha256 | B17: SHA-256 | C17: text | D17: all files | E17: Content fingerprint | F17: 8a42... | G17: text.equals,text.not_equals,text.starts_with
A18: duplicate_group | B18: Duplicate Group | C18: category | D18: all files | E18: Hash/similar group ID | F18: DUP-0042 | G18: cat.is,cat.is_not,text.equals
A19: path_depth | B19: Path Depth | C19: number | D19: all objects | E19: Folder nesting depth | F19: 7 | G19: num.gt,num.gte,num.lt,num.lte,num.eq,num.between
A20: is_hidden | B20: Hidden | C20: boolean | D20: all objects | E20: Hidden/system flag | F20: TRUE | G20: bool.true,bool.false
A21: is_folder | B21: Is Folder | C21: boolean | D21: folders | E21: Object is folder | F21: TRUE | G21: bool.true,bool.false
A22: date_created | B22: Date Created | C22: date | D22: all objects | E22: Filesystem created date | F22: 46196 | G22: date.before,date.after,date.exactly,date.between,date.last_days,date.older_than_days,date.today,date.yesterday,date.this_month,date.this_year
A23: date_modified | B23: Date Modified | C23: date | D23: all objects | E23: Filesystem modified date | F23: 46196 | G23: date.before,date.after,date.exactly,date.between,date.last_days,date.older_than_days,date.today,date.yesterday,date.this_month,date.this_year
A24: date_accessed | B24: Date Accessed | C24: date | D24: all objects | E24: Filesystem accessed date | F24: 46196 | G24: date.before,date.after,date.exactly,date.between,date.last_days,date.older_than_days,date.today,date.yesterday,date.this_month,date.this_year
A25: date_scanned | B25: Date Scanned | C25: date | D25: FIS | E25: Last scanner run date | F25: 46196 | G25: date.before,date.after,date.last_days,date.older_than_days
A26: photo_camera_make | B26: Photo Camera Make | C26: text | D26: photo/image | E26: EXIF camera manufacturer | F26: Canon | G26: text.contains,text.equals,text.regex
A27: photo_camera_model | B27: Photo Camera Model | C27: text | D27: photo/image | E27: EXIF camera model | F27: EOS R6 | G27: text.contains,text.equals,text.regex
A28: photo_lens_model | B28: Photo Lens Model | C28: text | D28: photo/image | E28: EXIF lens | F28: RF 24-70 | G28: text.contains,text.equals,text.regex
A29: photo_aperture | B29: Photo Aperture | C29: number | D29: photo/image | E29: F-number | F29: 2.8 | G29: num.gt,num.gte,num.lt,num.lte,num.eq,num.between
A30: photo_shutter_speed | B30: Photo Shutter Speed | C30: number | D30: photo/image | E30: Exposure time seconds | F30: 0.0167 | G30: num.gt,num.gte,num.lt,num.lte,num.eq,num.between
A31: photo_iso | B31: Photo ISO | C31: number | D31: photo/image | E31: ISO sensitivity | F31: 800 | G31: num.gt,num.gte,num.lt,num.lte,num.eq,num.between
A32: photo_focal_length | B32: Photo Focal Length | C32: number | D32: photo/image | E32: Focal length mm | F32: 50 | G32: num.gt,num.gte,num.lt,num.lte,num.eq,num.between
A33: photo_brightness | B33: Photo Brightness | C33: number | D33: photo/image | E33: Brightness value | F33: 0.6 | G33: num.gt,num.gte,num.lt,num.lte,num.eq,num.between
A34: photo_color_space | B34: Photo Color Space | C34: category | D34: photo/image | E34: sRGB/AdobeRGB/etc. | F34: sRGB | G34: cat.is,cat.is_not,cat.in,cat.not_in
A35: photo_compression | B35: Photo Compression | C35: category | D35: photo/image | E35: Compression metadata | F35: JPEG | G35: cat.is,cat.is_not,text.contains
A36: photo_date_taken | B36: Photo Date Taken | C36: date | D36: photo/image | E36: EXIF date original | F36: 46196 | G36: date.before,date.after,date.between,date.last_days,date.older_than_days
A37: photo_width | B37: Photo Width | C37: number | D37: photo/image | E37: Pixel width | F37: 1920 | G37: num.gt,num.gte,num.lt,num.lte,num.eq,num.between
A38: photo_height | B38: Photo Height | C38: number | D38: photo/image | E38: Pixel height | F38: 1080 | G38: num.gt,num.gte,num.lt,num.lte,num.eq,num.between
A39: photo_gps_exists | B39: Photo GPS Exists | C39: boolean | D39: photo/image | E39: EXIF GPS present | F39: FALSE | G39: bool.true,bool.false,exists.exists,exists.missing
A40: audio_duration | B40: Audio Duration | C40: number | D40: audio/video | E40: Seconds | F40: 3600 | G40: num.gt,num.gte,num.lt,num.lte,num.eq,num.between
A41: audio_artist | B41: Audio Artist | C41: text | D41: audio | E41: ID3 artist | F41: David | G41: text.contains,text.equals,text.regex
...

Sheet Operators
A1: Operators Registry
A2: Canonical operator list by data type. Use labels in the UI; operator_id is what code should read.
A4: operator_id | B4: label | C4: data_type | D4: description | E4: example
A5: text.contains | B5: contains | C5: text | D5: case-insensitive substring match | E5: name contains invoice
A6: text.not_contains | B6: not_contains | C6: text | D6: negative substring match | E6: path not_contains archive
A7: text.starts_with | B7: starts_with | C7: text | D7: begins with string | E7: name starts_with TP__
A8: text.ends_with | B8: ends_with | C8: text | D8: ends with string | E8: name ends_with .backup
A9: text.equals | B9: equals | C9: text | D9: exact match | E9: tag equals canonical
A10: text.not_equals | B10: not_equals | C10: text | D10: not exact match | E10: folder not_equals Windows
A11: text.regex | B11: regex | C11: text | D11: regular expression | E11: name regex (?i)final|draft
A12: text.empty | B12: empty | C12: text | D12: empty value | E12: tag empty
A13: text.not_empty | B13: not_empty | C13: text | D13: has any value | E13: content not_empty
A14: cat.is | B14: is | C14: category | D14: exact category match | E14: type is image
A15: cat.is_not | B15: is_not | C15: category | D15: not category | E15: risk_class is_not protected
... A39: exists.missing | B39: missing | C39: exists | D39: value/file/metadata missing | E39: sidecar missing

Sheet Actions_Master
A1: Actions Master Registry
A2: Every action the File Intelligence System can propose or execute, with safety defaults.
A4: action_id | B4: action_name | C4: action_family | D4: description | E4: destructive_level | F4: requires_preview | G4: requires_approval | H4: writes_ledger | I4: rollback_possible | J4: default_safety | K4: best_view_modes
A5: scan | B5: Scan | C5: Inspect | D5: Inventory files/folders without modifying anything | E5: none | F5: No | G5: No | H5: Yes | I5: N/A | J5: preview_only | K5: single pane;tree;details
A6: build_cache | B6: Build Memory / Cache | C6: Inspect | D6: Write file inventory, hashes, and basic features to SQLite | E6: none | F6: No | G6: No | H6: Yes | I6: N/A | J6: preview_only | K6: details
A7: classify | B7: Classify | C7: Analyze | D7: Assign type, role, domain, route candidates, and confidence | E7: none | F7: No | G7: No | H7: Yes | I7: N/A | J7: preview_only | K7: details;grouped
A8: detect_symptoms | B8: Detect Symptoms | C8: Analyze | D8: Detect folder/file pathologies and risks | E8: none | F8: No | G8: No | H8: Yes | I8: N/A | J8: preview_only | K8: grouped;dashboard
A9: tag | B9: Tag | C9: Metadata | D9: Apply tags to sidecar/DB without moving files | E9: low | F9: Yes | G9: Optional | H9: Yes | I9: Yes | J9: suggest_only | K9: details;grouped
A10: rename | B10: Rename | C10: Action | D10: Change filename or folder name | E10: medium | F10: Yes | G10: Yes | H10: Yes | I10: Yes | J10: approval_required | K10: details;preview
A11: move | B11: Move | C11: Action | D11: Move files/folders to a target path | E11: medium | F11: Yes | G11: Yes | H11: Yes | I11: Partial | J11: approval_required | K11: dual pane;tree;preview
A12: copy | B12: Copy | C12: Action | D12: Copy files/folders while preserving originals | E12: low | F12: Yes | G12: Optional | H12: Yes | I12: Yes | J12: suggest_only | K12: dual pane;tree;preview
A13: archive | B13: Archive | C13: Action | D13: Move/copy inactive files to dated archive lane | E13: medium | F13: Yes | G13: Yes | H13: Yes | I13: Partial | J13: approval_required | K13: tree;preview
A14: delete_later | B14: Delete Later | C14: Action | D14: Move to quarantine/delete-later review lane; never direct delete | E14: high | F14: Yes | G14: Yes | H14: Yes | I14: Yes | J14: approval_required | K14: review queue;preview
A15: quarantine | B15: Quarantine | C15: Risk | D15: Isolate suspicious/private/unknown files from public or working zones | E15: medium | F15: Yes | G15: Yes | H15: Yes | I15: Yes | J15: approval_required | K15: review queue
... A36: report | B36: Report | C36: Govern | D36: Generate consulting report, CSVs, risk register, appendix | E36: none | F36: No | G36: Optional | H36: Yes | I36: N/A | J36: preview_only | K36: dashboard;report

Sheet Action_Map
A1: Action Map
A2: High-level mental model: every button belongs inside a stage. Use this to keep the UI intuitive while retaining advanced power.
A4: SCOPE / SETUP | C4: LOOK | E4: UNDERSTAND | G4: DESIGN | I4: ACT | K4: GOVERN
A5: Scope Interview | C5: scan | E5: classify | G5: create_folder | I5: rename | K5: review
A6: Allowed Roots | C6: build_cache | E6: detect_symptoms | G6: create_blank_file | I6: move | K6: schedule
A7: Protected Items | C7: hash | E7: tag | G7: link_hub | I7: copy | K7: notify
A8: Safety Mode | C8: compare | E8: create_sidecar | G8: workflow_template | I8: archive | K8: sync
A9: Business/Personal Map | C9: report | E9: update_sidecar | G9: view_mode | I9: delete_later | K9: publish
I10: quarantine | K10: unpublish
I11: protect | K11: run_script
I12: backup | K12: report
I13: restore
A20: action_id | B20: name | C20: family | D20: destructive | E20: preview | F20: approval | G20: rollback | H20: default_safety | I20: best_views
A21: scan | B21: Scan | C21: Inspect | D21: none | E21: No | F21: No | G21: N/A | H21: preview_only | I21: single pane;tree;details
A22: build_cache | B22: Build Memory / Cache | C22: Inspect | D22: none | E22: No | F22: No | G22: N/A | H22: preview_only | I22: details
A23: classify | B23: Classify | C23: Analyze | D23: none | E23: No | F23: No | G23: N/A | H23: preview_only | I23: details;grouped
A24: detect_symptoms | B24: Detect Symptoms | C24: Analyze | D24: none | E24: No | F24: No | G24: N/A | H24: preview_only | I24: grouped;dashboard
A25: tag | B25: Tag | C25: Metadata | D25: low | E25: Yes | F25: Optional | G25: Yes | H25: suggest_only | I25: details;grouped
A26: rename | B26: Rename | C26: Action | D26: medium | E26: Yes | F26: Yes | G26: Yes | H26: approval_required | I26: details;preview
A27: move | B27: Move | C27: Action | D27: medium | E27: Yes | F27: Yes | G27: Partial | H27: approval_required | I27: dual pane;tree;preview
A28: copy | B28: Copy | C28: Action | D28: low | E28: Yes | F28: Optional | G28: Yes | H28: suggest_only | I28: dual pane;tree;preview
A29: archive | B29: Archive | C29: Action | D29: medium | E29: Yes | F29: Yes | G29: Partial | H29: approval_required | I29: tree;preview
A30: delete_later | B30: Delete Later | C30: Action | D30: high | E30: Yes | F30: Yes | G30: Yes | H30: approval_required | I30: review queue;preview
A31: quarantine | B31: Quarantine | C31: Risk | D31: medium | E31: Yes | F31: Yes | G31: Yes | H31: approval_required | I31: review queue
... A52: report | B52: Report | C52: Govern | D52: none | E52: No | F52: Optional | G52: N/A | H52: preview_only | I52: dashboard;report

Sheet Action_Sequence_Matrix
A1: Action Sequence Matrix
A2: Each action has a safe sequence. This is the bridge between UI buttons and backend execution.
A4: action_sheet | B4: action_id | C4: title | D4: step_1 | E4: step_2 | F4: step_3 | G4: step_4 | H4: step_5 | I4: default_guardrail | J4: notes
A5: LOOK_SCAN | B5: scan | C5: Look / Scan | D5: Choose allowed roots | user-selected folders only | E5: Inventory files/folders | path/type/size/date | F5: Hash critical candidates | optional/threshold | G5: Detect basic risks | project roots/secrets/system | H5: Report scan summary | counts and unknowns | I5: GR-005/GR-006 | J5: Build read-only inventory and memory before any action.
A6: CLASSIFY | B6: classify | C6: Understand / Classify | D6: Read inventory | from scan cache | E6: Apply deterministic labels | extension/MIME/name/path/content | F6: Vote across signals | weighted family/role scores | G6: Queue unknowns | unknown tokens/extensions | H6: Write classifications | SQLite + sidecar candidates | I6: GR-005/GR-006 | J6: Assign type, role, domain, destination candidates, and confidence.
A7: TAG | B7: tag | C7: Tag / Metadata | D7: Select file set | rules/query | E7: Preview tags | domain/role/status/risk | F7: Approval optional | low-risk metadata | G7: Write tags | SQLite/.chi | H7: Ledger | tag before/after | I7: GR-005/GR-006 | J7: Apply safe metadata or sidecar tags without moving files.
A8: RENAME | B8: rename | C8: Rename | D8: Select candidates | name rot/low-risk loose files | E8: Generate proposed names | schema/template/markov suggestions | F8: Validate collisions | target names unique | G8: Approve rename | row-level approval | H8: Execute + ledger | before/after path | I8: GR-005/GR-006 | J8: Suggest and apply safer names only after preview.
A9: MOVE | B9: move | C9: Move | D9: Select matched set | query/symptom/workflow | E9: Score destinations | where candidates + rival margin | F9: Preview before/after | exact old/new paths | G9: Approval | row or batch approval | H9: Execute/verify | move and verify hash/path | I9: GR-005/GR-006 | J9: Move files/folders to better home with preview and rollback trail.
A10: COPY | B10: copy | C10: Copy | D10: Select matched set | query/symptom/workflow | E10: Choose target | backup/review/archive | F10: Preview copy | old/new paths | G10: Execute copy | copy files/metadata/sidecars | H10: Ledger/report | before/after + verification | I10: GR-005/GR-006 | J10: Copy files/folders safely, often before move/archive/delete-later.
A11: ARCHIVE | B11: archive | C11: Archive | D11: Identify inactive set | age/status/folder role | E11: Choose archive lane | date/project/domain | F11: Preview archive | exact paths | G11: Execute archive | move/copy + manifest | H11: Generate archive report | summary + manifest | I11: GR-005/GR-006 | J11: Move/copy inactive material to dated archive with manifest.
A12: DELETE_LATER | B12: delete_later | C12: Delete Later / Quarantine | D12: Select candidates | duplicates/temp/debris | E12: Confirm keeper/protection | duplicates only after compare | F12: Move to delete-later | quarantine folder | G12: Hold period | minimum days | H12: Final review/report | manual decision later | I12: GR-005/GR-006 | J12: Never delete directly; move candidates into review/quarantine with hold period.
A13: PROTECT | B13: protect | C13: Protect / Do Not Touch | D13: Detect protected patterns | system/project/secrets/client/tax | E13: Confirm protection | auto for critical, review for high | F13: Write protected flag | SQLite/.chi | G13: Block incompatible actions | guardrail matrix | H13: Report protected items | risk register | I13: GR-005/GR-006 | J13: Mark objects as blocked from dangerous automation.
A14: COMPARE_DEDUPE | B14: dedupe | C14: Compare / Deduplicate | D14: Hash candidates | exact hash groups | E14: Compare near duplicates | name/size/date/content | F14: Select keeper candidate | newest/original/path/manual | G14: Preview delete-later/archive | no direct delete | H14: Ledger/report | duplicate group evidence | I14: GR-005/GR-006 | J14: Find duplicate/mirror/version issues without unsafe deletion.
A15: SIDECAR | B15: create_sidecar | C15: .chi Sidecar | D15: Detect missing/stale sidecars | source vs .chi | E15: Build profile | role/domain/risk/evidence | F15: Preview sidecar | human-readable record | G15: Write sidecar | markdown-compatible .chi | H15: Update DB | sidecar hash/time | I15: GR-005/GR-006 | J15: Create/update file intelligence records beside source files.
... A18: ANALYZE_EXTRACT | B18: ocr | C18: Analyze / OCR / Transcribe | D18: Select extractable files | PDF/image/audio/video | E18: Choose extractor | OCR/transcribe/text parse | F18: Preview cost/privacy | API/local choice | G18: Run extraction | generate text sidecar | H18: Reclassify/report | content signals improve | I18: GR-005/GR-006 | J18: Extract text and metadata to improve classification.

Sheet View_Modes
A1: View Modes / Layout Registry
A2: Single-pane, dual-pane, flat, grouped, tree, thumbnail, compare, review queue, and other display modes.
A4: view_id | B4: view_name | C4: best_for | D4: supports_preview | E4: supports_compare | F4: risk | G4: notes
A5: single_pane | B5: Single Pane | C5: Simple browsing and review | D5: No | E5: No | F5: Low | G5: Works for lightweight inspection.
A6: dual_pane | B6: Dual Pane | C6: Copy/move/compare source and target | D6: Yes | E6: Yes | F6: Medium | G6: Recommended for move/copy/sync.
A7: horizontal_split | B7: Horizontal Split | C7: Compare source above target | D7: Yes | E7: Yes | F7: Medium | G7: Good on widescreen dashboards.
A8: vertical_split | B8: Vertical Split | C8: Traditional two-panel file manager | D8: Yes | E8: Yes | F8: Medium | G8: Good for copy/move/compare.
A9: flat | B9: Flat View | C9: All files in one list, no folders | D9: Yes | E9: No | F9: Medium | G9: Great for bulk rename/sort.
A10: grouped | B10: Grouped View | C10: Cluster by extension/domain/symptom | D10: Yes | E10: No | F10: Low | G10: Best for diagnosis.
A11: tree | B11: Folder Tree | C11: Folder hierarchy and scaffolding | D11: Yes | E11: No | F11: Low | G11: Best for structure planning.
A12: thumbnail | B12: Thumbnail View | C12: Images/video visual sorting | D12: Yes | E12: No | F12: Low | G12: Best for pictures and assets.
A13: details | B13: Details Table | C13: Metadata-rich decisions | D13: Yes | E13: No | F13: Low | G13: Best default for rule preview.
A14: metadata | B14: Metadata Pane | C14: Inspect EXIF/PDF/audio tags | D14: Yes | E14: No | F14: Low | G14: Used beside details/preview.
A15: preview | B15: Preview Pane | C15: View content before action | D15: Yes | E15: No | F15: Low | G15: Required for ambiguous files.
... A22: settings | B22: Settings | C22: Thresholds and automation controls | D22: No | E22: No | F22: Medium | G22: Governance and learned preferences.

Sheet Guardrails
A1: Guardrail Grammar
A2: Non-negotiable safety rules. These are not filters; they block unsafe automation.
A4: guardrail_id | B4: name | C4: severity | D4: description | E4: applies_to | F4: default_behavior
A5: GR-001 | B5: Never touch system folders | C5: critical | D5: Blocks Windows, Program Files, ProgramData, AppData unless explicitly whitelisted. | E5: all destructive actions | F5: blocked
A6: GR-002 | B6: Never delete directly | C6: critical | D6: Deletion always routes to delete-later quarantine with hold period. | E6: delete/delete_later | F6: enforced
A7: GR-003 | B7: Protect project roots | C7: critical | D7: Detect .git, package.json, node_modules, venv, lockfiles, solution/project files. | E7: move/rename/delete/archive | F7: review_required
A8: GR-004 | B8: Protect secrets/config | C8: critical | D8: .env, keys, tokens, credentials, config DBs never auto-publish/move/delete. | E8: all public/destructive actions | F8: blocked
A9: GR-005 | B9: Write ledger for every action | C9: high | D9: Before/after path, hash, confidence, user decision, timestamp. | E9: all actions | F9: required
A10: GR-006 | B10: Preview before action | C10: high | D10: Show exact before/after plan before execution. | E10: move/copy/rename/archive/delete_later | F10: required
A11: GR-007 | B11: Confidence gate | C11: high | D11: Below review threshold = review only; above auto threshold = still block if risky. | E11: classify/routing | F11: enforced
A12: GR-008 | B12: Hash before duplicate decisions | C12: high | D12: No duplicate keeper/delete-later decision without hash or content check. | E12: dedupe/delete_later | F12: required
A13: GR-009 | B13: Protect public/private boundary | C13: high | D13: Never publish private/source/client/credential files. | E13: publish/sync | F13: blocked
A14: GR-010 | B14: Max files per run | C14: medium | D14: Automation stops if file count exceeds threshold unless user overrides. | E14: automation | F14: required
A15: GR-011 | B15: Rollback plan required | C15: medium | D15: Move/rename/archive must write rollback rows before execution. | E15: move/rename/archive | F15: required
A16: GR-012 | B16: Skip low-confidence actions | C16: medium | D16: Actions on low-confidence files become suggestions only. | E16: all actions | F16: suggest_only

Sheet Automation_Triggers
A1: Automation Triggers
A2: Events that can launch a rule. Triggers never execute alone; they require selection, guardrails, preview, approval, and ledger.
A4: trigger_id | B4: trigger_name | C4: event_source | D4: allowed_actions | E4: description | F4: requires_guardrails
A5: manual_run | B5: Manual Run | C5: user | D5: any | E5: User starts a scan/workflow. | F5: Yes
A6: folder_watch | B6: Folder Watch | C6: filesystem | D6: scan,classify,review | E6: New/changed files in watched folder. | F6: Yes
A7: file_created | B7: File Created | C7: filesystem | D7: scan,classify,tag,review | E7: New file appears. | F7: Yes
A8: file_modified | B8: File Modified | C8: filesystem | D8: scan,update_sidecar,review | E8: Tracked file modified. | F8: Yes
A9: downloaded | B9: Download Detected | C9: filesystem | D9: scan,classify,route | E9: New file in Downloads. | F9: Yes
A10: schedule_daily | B10: Daily Schedule | C10: clock | D10: scan,report | E10: Scheduled daily audit. | F10: Optional
A11: schedule_weekly | B11: Weekly Schedule | C11: clock | D11: scan,report,review | E11: Scheduled weekly cleanup review. | F11: Optional
A12: sidecar_missing | B12: .chi Missing | C12: scanner | D12: create_sidecar,review | E12: Source file has no sidecar. | F12: Optional
A13: sidecar_stale | B13: .chi Stale | C13: scanner | D13: update_sidecar,review | E13: Sidecar hash/date behind source. | F13: Optional
A14: duplicate_detected | B14: Duplicate Detected | C14: scanner | D14: compare,dedupe,review | E14: Hash/name/size duplicate group found. | F14: Yes
A15: unknown_token | B15: Unknown Token Found | C15: scanner | D15: review,approve_term | E15: Filename/path token not in registry. | F15: Yes
... A17: approval_received | B17: Approval Received | C17: user | D17: learn,execute,ledger | E17: User approved/edited/rejected recommendation. | F17: Yes

Sheet Automation_Rules
A1: Automation Rules / Action Grammar
A2: A complete rule = trigger + selection + diagnosis + guardrails + action sequence + approval + ledger.
A4: automation_id | B4: enabled | C4: trigger | D4: selection_rule_group | E4: diagnosis_required | F4: action_1 | G4: action_2 | H4: action_3 | I4: action_4 | J4: action_5 | K4: guardrail_profile | L4: approval_mode | M4: view_mode | N4: max_files_per_run | O4: schedule | P4: notes
A5: AUTO-001 | B5: FALSE | C5: downloaded | D5: RULE-001 | E5: Yes | F5: scan | G5: classify | H5: detect_symptoms | I5: report | K5: GR-006 | L5: preview_only | M5: details | N5: 500 | O5: manual | P5: Downloads diagnosis only
A6: AUTO-002 | B6: FALSE | C6: duplicate_detected | D6: RULE-004 | E6: Yes | F6: hash | G6: compare | H6: dedupe | I6: delete_later | J6: report | K6: GR-008 | L6: approval_required | M6: compare | N6: 200 | O6: manual | P6: Duplicate cleanup chain
A7: AUTO-003 | B7: FALSE | C7: sidecar_missing | D7: RULE-001 | E7: No | F7: create_sidecar | G7: report | K7: GR-005 | L7: suggest_only | M7: details | N7: 1000 | O7: weekly | P7: Generate .chi sidecars
A8: AUTO-004 | B8: FALSE | E8: Yes | L8: preview_only | M8: details | N8: 100 | O8: manual
A9: AUTO-005 | B9: FALSE | E9: Yes | L9: preview_only | M9: details | N9: 100 | O9: manual
A10: AUTO-006 | B10: FALSE | E10: Yes | L10: preview_only | M10: details | N10: 100 | O10: manual
A11: AUTO-007 | B11: FALSE | E11: Yes | L11: preview_only | M11: details | N11: 100 | O11: manual
A12: AUTO-008 | B12: FALSE | E12: Yes | L12: preview_only | M12: details | N12: 100 | O12: manual
A13: AUTO-009 | B13: FALSE | E13: Yes | L13: preview_only | M13: details | N13: 100 | O13: manual
A14: AUTO-010 | B14: FALSE | E14: Yes | L14: preview_only | M14: details | N14: 100 | O14: manual
A15: AUTO-011 | B15: FALSE | E15: Yes | L15: preview_only | M15: details | N15: 100 | O15: manual
A16: AUTO-012 | B16: FALSE | E16: Yes | L16: preview_only | M16: details | N16: 100 | O16: manual
A17: AUTO-013 | B17: FALSE | E17: Yes | L17: preview_only | M17: details | N17: 100 | O17: manual
A18: AUTO-014 | B18: FALSE | E18: Yes | L18: preview_only | M18: details | N18: 100 | O18: manual
A19: AUTO-015 | B19: FALSE | E19: Yes | L19: preview_only | M19: details | N19: 100 | O19: manual
... A34: AUTO-030 | B34: FALSE | E34: Yes | L34: preview_only | M34: details | N34: 100 | O34: manual

Sheet Compatibility_Matrix
A1: Action Compatibility Matrix
A2: Which actions can be chained together, which are conditional, and which are blocked.
A4: action_or_signal_a | B4: action_b | C4: compatibility | D4: condition | E4: risk | F4: reason
A5: scan | B5: classify | C5: Yes | D5: Scan must precede classification. | E5: low | F5: classification needs inventory
A6: scan | B6: move | C6: No | D6: Cannot move before inventory/safety. | E6: high | F6: unknown risk
A7: hash | B7: dedupe | C7: Required | D7: Hash required for exact duplicate decisions. | E7: high | F7: prevents false duplicate deletion
A8: dedupe | B8: delete_later | C8: Conditional | D8: Only after keeper review and hash evidence. | E8: critical | F8: delete-later not direct delete
A9: rename | B9: move | C9: Conditional | D9: Allowed if both previewed and rollback ledger exists. | E9: medium | F9: two path changes
A10: copy | B10: move | C10: Conditional | D10: Copy can precede move as backup. | E10: medium | F10: safer migration
A11: archive | B11: report | C11: Yes | D11: Archive should produce manifest/report. | E11: low | F11: audit trail
A12: protect | B12: move | C12: Blocks | D12: Protected items cannot move automatically. | E12: critical | F12: do-not-touch policy
A13: protect | B13: rename | C13: Blocks | D13: Protected items cannot rename automatically. | E13: critical | F13: do-not-touch policy
A14: protect | B14: delete_later | C14: Blocks | D14: Protected items cannot be deleted by automation. | E14: critical | F14: do-not-touch policy
A15: classify | B15: tag | C15: Yes | D15: Tag can store classification safely. | E15: low | F15: metadata only
... A28: review | B28: learn | C28: Yes | D28: Approved/rejected actions train preferences. | E28: low | F28: preference loop

Sheet Symptoms
A1: Symptom Taxonomy
A2: File/folder pathologies the scanner should detect before proposing actions.
A4: symptom_id | B4: symptom | C4: category | D4: severity | E4: description | F4: evidence_pattern | G4: recommended_action
A5: SYM-001 | B5: program_root_danger | C5: Safety / Do-Not-Touch | D5: critical | E5: Project/app dependency markers found. | F5: .git/package.json/node_modules/.venv/.sln | G5: protect; report only
A6: SYM-002 | B6: config_leak | C6: Safety / Do-Not-Touch | D6: critical | E6: Secrets/config files outside protected lane. | F6: .env/API/key/token | G6: quarantine from publish; protect
A7: SYM-003 | B7: system_folder_danger | C7: Safety / Do-Not-Touch | D7: critical | E7: System/program folder selected. | F7: Windows/Program Files/AppData | G7: block actions
A8: SYM-004 | B8: database_state_file | C8: Safety / Do-Not-Touch | D8: high | E8: DB/application state file mixed with loose files. | F8: .db/.sqlite/.pst/catalog | G8: protect; backup
A9: SYM-005 | B9: extension_swamp | C9: Structure | D9: medium | E9: Many unrelated extensions in one folder. | F9: extension entropy high | G9: separate by family after scan
A10: SYM-006 | B10: media_dump | C10: Structure | D10: medium | E10: Images/audio/video mixed with weak folder structure. | F10: image/video/audio ratio high | G10: sort by source/date/type
A11: SYM-007 | B11: document_chaos | C11: Structure | D11: medium | E11: Documents mixed without domain/project grouping. | F11: pdf/docx/xlsx/md mix | G11: classify by role/domain
A12: SYM-008 | B12: archive_pile | C12: Lifecycle | D12: medium | E12: Archives mixed with live files. | F12: zip/rar/7z/backups | G12: archive lane / unpack-review
A13: SYM-009 | B13: tiny_folder_debris | C13: Lifecycle | D13: low | E13: Empty/tiny folders and sync debris. | F13: 0-2 files/no content | G13: delete-later review
A14: SYM-010 | B14: duplicate_cluster | C14: Duplication | D14: high | E14: Exact duplicates by hash. | F14: same hash | G14: choose keeper; review before delete-later
A15: SYM-011 | B15: near_duplicate_cluster | C15: Duplication | D15: medium | E15: Similar names/content, different hash. | F15: stem similarity | G15: compare; version chain
... A44: SYM-040 | B44: no_ledger_trail | C44: Governance | D44: high | E44: Actions without action record. | F44: no ledger rows | G44: block execution

Sheet Workflow_Templates
A1: Workflow Templates
A2: Preset sequences for common jobs. Each workflow is a repeatable consulting playbook.
A4: workflow_id | B4: workflow_name | C4: best_for | D4: default_sequence | E4: guardrails | F4: recommended_views | G4: notes
A5: WF-001 | B5: Downloads Quick Sort | C5: Loose mixed downloads | D5: Scan > Classify > Detect Symptoms > Preview Move > Review > Report | E5: GR-002;GR-005;GR-006;GR-007 | F5: details;review_queue | G5: Never touch installers/program roots without review.
A6: WF-002 | B6: Photo / PICS Cleanup | C6: Image-heavy folders | D6: Scan > Hash > Detect Duplicates > Classify Source > Preview Separate > Review > Report | E6: GR-005;GR-006;GR-008 | F6: thumbnail;metadata;review_queue | G6: Group screenshots/generated/camera/reference.
A7: WF-003 | B7: Business Records Audit | C7: Company/client/accounting/legal folders | D7: Scan > Protect Sensitive > Classify Roles > Unknown Terms Review > Proposed Architecture > Report | E7: GR-001;GR-002;GR-004;GR-005;GR-006 | F7: dashboard;details;review_queue | G7: Report-first; no moves until signoff.
A8: WF-004 | B8: Duplicate Cleanup | C8: Exact/near duplicate cleanup | D8: Scan > Hash > Compare > Dedupe Candidates > Keeper Review > Delete Later > Report | E8: GR-002;GR-005;GR-006;GR-008 | F8: compare;review_queue | G8: Delete later only; never direct deletion.
A9: WF-005 | B9: Project-Safe Code Cleanup | C9: Code/project directories | D9: Scan > Detect Project Roots > Protect > Report > Optional Copy/Archive | E9: GR-001;GR-003;GR-004;GR-005 | F9: tree;details | G9: Do not rename/move internals.
A10: WF-006 | B10: Theophysics Corpus Audit | C10: Research corpus | D10: Scan > .chi Sidecars > Domain/χ/Law Classification > Claim Engine > Gap Report | E10: GR-005;GR-006;GR-007 | F10: dashboard;details;review_queue | G10: Output claim atlas, corpus audit, repair queue.
A11: WF-007 | B11: AI Session Archive | C11: Raw GPT/Claude/Gemini exports | D11: Scan > Provenance Detect > Tag > Archive by Model/Date/Project > Report | E11: GR-005;GR-006;GR-007 | F11: details;grouped | G11: Preserve provenance and original text.
A12: WF-008 | B12: Website Publish Review | C12: Public/reviewer portal | D12: Scan > Public/Private Risk > Sidecar Check > Preview Publish > Approval > Report | E12: GR-004;GR-005;GR-006;GR-009 | F12: preview;details | G12: No private/source/secrets to public path.

Sheet Report_Sections
A1: Consulting Report Sections
A2: What a high-quality pre-action file intelligence report should contain.
A4: section_id | B4: section_name | C4: audience | D4: purpose | E4: importance
A5: RS-001 | B5: Executive Summary | C5: owner/manager | D5: Top counts, major risks, recommended first actions. | E5: High
A6: RS-002 | B6: Scope and Safety Boundaries | C6: all | D6: Scanned/excluded locations and no-modification statement. | E6: Critical
A7: RS-003 | B7: Corpus Inventory | C7: technical/owner | D7: Counts by file type, extension, size, age, folder depth. | E7: High
A8: RS-004 | B8: Domain/Role Map | C8: owner/reviewer | D8: Business/personal/domain areas discovered. | E8: High
A9: RS-005 | B9: Protected / Do-Not-Touch | C9: technical | D9: System/project/config/sensitive items. | E9: Critical
A10: RS-006 | B10: Symptom Diagnosis | C10: owner/technical | D10: Version sprawl, duplicates, extension swamp, etc. | E10: Critical
A11: RS-007 | B11: Duplicate Analysis | C11: technical | D11: Exact/near duplicates, sync conflicts, recoverable space. | E11: High
A12: RS-008 | B12: Risk & Anomaly Register | C12: technical/security | D12: Secrets, private-public boundary, project roots, unknowns. | E12: Critical
A13: RS-009 | B13: Unknowns & Review Queue | C13: operator | D13: Unknown tokens/extensions/low-confidence files and questions. | E13: High
A14: RS-010 | B14: Proposed Folder Architecture | C14: owner/operator | D14: Future state structure before moves. | E14: High
A15: RS-011 | B15: Proposed Action Plan | C15: operator | D15: Phase 0-7 execution plan. | E15: Critical
... A18: RS-014 | B18: Technical Appendix | C18: technical | D18: CSV/DB evidence, hashes, rules, action preview. | E18: High

Sheet Ledger_Schema
A1: Ledger Schema
A2: Every action should leave a rollback-capable evidence trail.
A4: field | B4: data_type | C4: description | D4: example | E4: requirement
A5: ledger_id | B5: text | C5: Unique action row ID | D5: ACT-20260623-0001 | E5: required
A6: timestamp_utc | B6: datetime | C6: UTC timestamp | D6: 46196.5 | E6: required
A7: user | B7: text | C7: User or process | D7: David | E7: required
A8: action_id | B8: category | C8: Action performed/proposed | D8: move | E8: required
A9: decision_id | B9: text | C9: Approval/rejection decision ref | D9: DEC-0001 | E9: required for execution
A10: rule_id | B10: text | C10: Selection/automation rule that created action | D10: RULE-001 | E10: optional
A11: source_path_before | B11: text | C11: Before path | D11: D:\Downloads\file.png | E11: required
A12: target_path_after | B12: text | C12: After path | D12: D:\PICS\file.png | E12: required for path actions
A13: file_hash_before | B13: text | C13: Hash before action | D13: sha256... | E13: required for destructive actions
A14: file_hash_after | B14: text | C14: Hash after action | D14: sha256... | E14: required for copy/move
A15: confidence | B15: number | C15: 0-100 confidence | D15: 82.5 | E15: required
A16: risk_score | B16: number | C16: 0-100 risk | D16: 15 | E16: required
A17: approval_status | B17: category | C17: approved/rejected/edited/pending | D17: approved | E17: required
A18: rollback_possible | B18: boolean | C18: Can action be reversed | D18: TRUE | E18: required
A19: status | B19: category | C19: planned/executed/error/rolled_back | D19: planned | E19: required
A20: error_message | B20: text | C20: Error if failed | E20: optional

Sheet Simulation_Lab
A1: OK you sold me
A2: Change input assumptions to estimate review burden, risk blocks, auto-suggestions, and report size before touching files.
A4: Input | B4: Value | C4: Notes | E4: Output | F4: Formula / Result | G4: Interpretation
A5: Workflow | B5: WF-001 | C5: Choose a workflow template | E5: Estimated high-risk files | F5: =ROUND(B6*B7,0) -> 500 | G5: Require protected review / blocked actions
A6: Total files | B6: 10000 | C6: Number of files in target scope | E6: Estimated low-confidence files | F6: =ROUND(B6*B8,0) -> 1800 | G6: Likely review queue
A7: High-risk % | B7: 0.05 | C7: Protected/sensitive/project-root expected share | E7: Estimated duplicate candidates | F7: =ROUND(B6*B9,0) -> 800 | G7: Need hash/compare/keeper review
A8: Low-confidence % | B8: 0.18 | C8: Expected low-confidence classifications | E8: Estimated files per run chunks | F8: =ROUNDUP(B6/B13,0) -> 20 | G8: How many batches to stay under guardrail
A9: Duplicate % | B9: 0.08 | C9: Expected duplicate candidates | E9: First review questions | F9: =MIN(B10,50) -> 50 | G9: Ask highest-impact unknown tokens first
A10: Unknown token groups | B10: 120 | C10: Distinct unknown terms/patterns | E10: Estimated ledger rows | F10: =B6+ROUND(B6*B9,0) -> 10800 | G10: At least one row per file plus duplicate action rows
A11: Auto threshold | B11: 0.9 | C11: Above this, safe suggestions can be auto-prepared | E11: Pre-action report required? | F11: =IF(B6>0,"YES","NO") -> YES | G11: Report before execution
A12: Review threshold | B12: 0.75 | C12: Below this, user review required | E12: Automation allowed? | F12: =IF(OR(B7>0.03,B8>0.2),"NO - REVIEW FIRST","MAYBE - PREVIEW ONLY") -> NO - REVIEW FIRST | G12: Safety gate
A13: Max files per run | B13: 500 | C13: Guardrail cap
A17: Scenario | B17: Total Files | C17: Risk % | D17: Low Conf % | E17: Dup % | F17: Unknown Groups | G17: Recommended Mode
A18: Small Downloads cleanup | B18: 1500 | C18: 0.02 | D18: 0.14 | E18: 0.06 | F18: 45 | G18: Preview + batch approve
A19: Photo/PICS folder | B19: 12000 | C19: 0.01 | D19: 0.1 | E19: 0.12 | F19: 80 | G19: Thumbnail review + dedupe
A20: Business archive | B20: 85000 | C20: 0.08 | D20: 0.22 | E20: 0.15 | F20: 800 | G20: Report-first, protect, unknowns review
A21: Code/projects folder | B21: 30000 | C21: 0.2 | D21: 0.12 | E21: 0.04 | F21: 250 | G21: Protect project roots
A22: Theophysics corpus | B22: 50000 | C22: 0.04 | D22: 0.18 | E22: 0.05 | F22: 600 | G22: .chi + claim/audit routing

Sheet Lists
A1: FIS Lists / Dropdown Sources
A2: This sheet feeds dropdowns. Add approved values here; Python can later read these lists.
A4: Fields | B4: Operators | C4: Actions | D4: View_Modes | E4: Guardrails | F4: Triggers | G4: Action_Families | H4: Risk_Levels | I4: Approval_Modes | J4: AND_OR | K4: Boolean | L4: Workflows
A5: name | B5: contains | C5: scan | D5: single_pane | E5: GR-001 | F5: manual_run | G5: Action | H5: none | I5: preview_only | J5: AND | K5: TRUE | L5: WF-001
A6: stem | B6: not_contains | C6: build_cache | D6: dual_pane | E6: GR-002 | F6: folder_watch | G6: Analyze | H6: low | I6: suggest_only | J6: OR | K6: FALSE | L6: WF-002
A7: extension | B7: starts_with | C7: classify | D7: horizontal_split | E7: GR-003 | F7: file_created | G7: Automation | H7: medium | I7: approval_required | L7: WF-003
A8: path | B8: ends_with | C8: detect_symptoms | D8: vertical_split | E8: GR-004 | F8: file_modified | G8: Govern | H8: high | I8: auto_after_threshold | L8: WF-004
A9: folder | B9: equals | C9: tag | D9: flat | E9: GR-005 | F9: downloaded | G9: Inspect | H9: critical | I9: blocked | L9: WF-005
A10: type | B10: not_equals | C10: rename | D10: grouped | E10: GR-006 | F10: schedule_daily | G10: Integration | L10: WF-006
A11: detected_type | B11: regex | C11: move | D11: tree | E11: GR-007 | F11: schedule_weekly | G11: Metadata | L11: WF-007
A12: mime_type | B12: empty | C12: copy | D12: thumbnail | E12: GR-008 | F12: sidecar_missing | G12: Risk | L12: WF-008
A13: size_bytes | B13: not_empty | C13: archive | D13: details | E13: GR-009 | F13: sidecar_stale | G13: Safety
A14: size_mb | B14: is | C14: delete_later | D14: metadata | E14: GR-010 | F14: duplicate_detected | G14: Scaffold
A15: tag | B15: is_not | C15: quarantine | D15: preview | E15: GR-011 | F15: unknown_token
A16: content | B16: in | C16: protect | D16: compare | E16: GR-012 | F16: low_confidence
A17: hash_sha256 | B17: not_in | C17: hash | D17: review_queue | F17: approval_received
A18: duplicate_group | B18: gt | C18: compare | D18: outline
A19: path_depth | B19: gte | C19: dedupe | D19: dashboard
A20: is_hidden | B20: lt | C20: create_folder | D20: terminal
A21: is_folder | B21: lte | C21: create_blank_file | D21: graph
A22: date_created | B22: eq | C22: create_sidecar | D22: settings
A23: date_modified | B23: neq | C23: update_sidecar
A24: date_accessed | B24: between | C24: ocr
A25: date_scanned | B25: before | C25: transcribe
A26: photo_camera_make | B26: after | C26: summarize
A27: photo_camera_model | B27: exactly | C27: link_hub
A28: photo_lens_model | B28: between | C28: sync
A29: photo_aperture | B29: last_days | C29: backup
A30: photo_shutter_speed | B30: older_than_days | C30: restore
A31: photo_iso | B31: today | C31: publish
A32: photo_focal_length | B32: yesterday | C32: unpublish
A33: photo_brightness | B33: this_week | C33: run_script
A34: photo_color_space | B34: this_month | C34: notify
... A36: photo_date_taken | B36: is_true | C36: report
A37: photo_width | B37: is_false
A38: photo_height | B38: exists
A39: photo_gps_exists | B39: missing
A40: audio_duration
A41: audio_artist
A42: audio_album
...

Sheet ACT_LOOK_SCAN
A1: Action Spec: Look / Scan
A2: Build read-only inventory and memory before any action.
A4: Input / Control | B4: Default / Notes | D4: Step | E4: Stage | F4: Control / Variable | G4: Guardrail | H4: Best View | I4: Output
A5: source_folder | D5: 1 | E5: Choose allowed roots | F5: user-selected folders only | G5: system/program folders excluded | H5: folder picker | I5: preview only
A6: scan_depth | D6: 2 | E6: Inventory files/folders | F6: path/type/size/date | G6: no writes to source | H6: details/tree | I6: ledger
A7: file_types | D7: 3 | E7: Hash critical candidates | F7: optional/threshold | G7: no duplicate action without hash | H7: details | I7: hash table
A8: hash_policy | D8: 4 | E8: Detect basic risks | F8: project roots/secrets/system | G8: block unsafe actions | H8: dashboard | I8: risk register
A9: exclude_folders | D9: 5 | E9: Report scan summary | F9: counts and unknowns | G9: no moves | H9: dashboard/report | I9: report.html
A10: max_files
A16: action_or_signal_a | B16: action_b | C16: compatibility | D16: condition | E16: risk | F16: reason | H16: Property | I16: Value
A17: scan | B17: classify | C17: Yes | D17: Scan must precede classification. | E17: low | F17: classification needs inventory | H17: action_id | I17: scan
A18: scan | B18: move | C18: No | D18: Cannot move before inventory/safety. | E18: high | F18: unknown risk | H18: action_name | I18: Scan
H19: action_family | I19: Inspect
H20: description | I20: Inventory files/folders without modifying anything
H21: destructive_level | I21: none
H22: requires_preview | I22: No
H23: requires_approval | I23: No
H24: writes_ledger | I24: Yes
H25: rollback_possible | I25: N/A
H26: default_safety | I26: preview_only
H27: best_view_modes | I27: single pane;tree;details

Sheet ACT_CLASSIFY
A1: Action Spec: Understand / Classify
A2: Assign type, role, domain, destination candidates, and confidence.
A4: Input / Control | B4: Default / Notes | D4: Step | E4: Stage | F4: Control / Variable | G4: Guardrail | H4: Best View | I4: Output
A5: classification_profile | D5: 1 | E5: Read inventory | F5: from scan cache | G5: requires scan | H5: details | I5: source data
A6: approved_terms | D6: 2 | E6: Apply deterministic labels | F6: extension/MIME/name/path/content | G6: no movement | H6: grouped | I6: evidence rows
